package com.github.technus.tectech.thing.metaTileEntity.multi;

import static com.github.technus.tectech.thing.casing.GT_Block_CasingsTT.texturePage;
import static com.github.technus.tectech.thing.casing.TT_Container_Casings.sBlockCasingsBA0;
import static com.github.technus.tectech.thing.casing.TT_Container_Casings.sBlockCasingsTT;
import static com.gtnewhorizon.structurelib.structure.StructureUtility.*;
import static gregtech.api.enums.GT_HatchElement.*;
import static gregtech.api.util.GT_StructureUtility.buildHatchAdder;
import static gregtech.api.util.GT_Utility.formatNumbers;
import static net.minecraft.util.StatCollector.translateToLocal;

import java.util.*;

import com.github.technus.tectech.thing.metaTileEntity.multi.base.*;
import gregtech.api.metatileentity.implementations.GT_MetaTileEntity_Hatch;
import net.minecraft.client.renderer.texture.IIconRegister;
import net.minecraft.entity.player.EntityPlayer;
import net.minecraft.entity.player.EntityPlayerMP;
import net.minecraft.item.ItemStack;
import net.minecraft.nbt.NBTTagCompound;
import net.minecraft.util.StatCollector;
import net.minecraftforge.fluids.FluidStack;

import org.apache.commons.lang3.tuple.Pair;

import com.github.technus.tectech.thing.casing.TT_Container_Casings;
import com.github.technus.tectech.thing.metaTileEntity.multi.base.render.TT_RenderedExtendedFacingTexture;
import com.github.technus.tectech.util.CommonValues;
import com.google.common.collect.ImmutableList;
import com.gtnewhorizon.structurelib.alignment.constructable.IConstructable;
import com.gtnewhorizon.structurelib.alignment.constructable.ISurvivalConstructable;
import com.gtnewhorizon.structurelib.structure.IItemSource;
import com.gtnewhorizon.structurelib.structure.IStructureDefinition;

import cpw.mods.fml.relauncher.Side;
import cpw.mods.fml.relauncher.SideOnly;
import gregtech.api.GregTech_API;
import gregtech.api.enums.Materials;
import gregtech.api.enums.Textures;
import gregtech.api.enums.TierEU;
import gregtech.api.interfaces.IGlobalWirelessEnergy;
import gregtech.api.interfaces.ITexture;
import gregtech.api.interfaces.metatileentity.IMetaTileEntity;
import gregtech.api.interfaces.tileentity.IGregTechTileEntity;
import gregtech.api.metatileentity.implementations.GT_MetaTileEntity_Hatch_Input;
import gregtech.api.metatileentity.implementations.GT_MetaTileEntity_Hatch_InputBus;
import gregtech.api.util.*;
import gregtech.common.tileentities.machines.GT_MetaTileEntity_Hatch_OutputBus_ME;
import gregtech.common.tileentities.machines.GT_MetaTileEntity_Hatch_Output_ME;

public class GT_MetaTileEntity_EM_ForgeOfGods extends GT_MetaTileEntity_MultiblockBase_EM
        implements IConstructable, IGlobalWirelessEnergy, ISurvivalConstructable {

    // region variables
    private static Textures.BlockIcons.CustomIcon ScreenOFF;
    private static Textures.BlockIcons.CustomIcon ScreenON;

    Parameters.Group.ParameterIn[] parallelParameter;
    Parameters.Group.ParameterIn[] fuelConsumptionParameter;

    private int spacetimeCompressionFieldMetadata = -1;
    private int solenoidCoilMetadata = -1;
    private static final int TICKS_BETWEEN_FUEL_DRAIN = 100;

    private GT_MetaTileEntity_Hatch_Input fuelInputHatch;
    private String userUUID = "";

    @Override
    public int survivalConstruct(ItemStack stackSize, int elementBudget, IItemSource source, EntityPlayerMP actor) {
        if (mMachine) return -1;
        int realBudget = elementBudget >= 200 ? elementBudget : Math.min(200, elementBudget * 5); // 200 blocks max per
        // placement.
        return survivialBuildPiece(STRUCTURE_PIECE_MAIN, stackSize, 31, 34, 0, realBudget, source, actor, false, true);
    }

    protected static final String STRUCTURE_PIECE_MAIN = "main";

    private static final IStructureDefinition<GT_MetaTileEntity_EM_ForgeOfGods> STRUCTURE_DEFINITION = IStructureDefinition
            .<GT_MetaTileEntity_EM_ForgeOfGods>builder()
            .addShape(
                    "main",
                    transpose(
                            new String[][] {
                                    { "                                                                     ",
                                            "                                                                     ",
                                            "                                                                     ",
                                            "                                                                     ",
                                            "                                                                     ",
                                            "                                                                     ",
                                            "                                                                     ",
                                            "                                                                     ",
                                            "                                                                     ",
                                            "                                                                     ",
                                            "                                                                     ",
                                            "                                                                     ",
                                            "                                                                     ",
                                            "                                                                     ",
                                            "                                                                     ",
                                            "                                                                     ",
                                            "                                                                     ",
                                            "                                                                     ",
                                            "                                                                     ",
                                            "                                                                     ",
                                            "                                                                     ",
                                            "                                                                     ",
                                            "                                                                     ",
                                            "                                                                     ",
                                            "                                                                     ",
                                            "                                                                     ",
                                            "                                   CC                                ",
                                            "                                   CCCC                              ",
                                            "                                     CCC                             ",
                                            "                                                                     ",
                                            "                                                                     ",
                                            "                                                                     ",
                                            "                                                                     ",
                                            "                                                                     ",
                                            "                                                                     ",
                                            "                                                                     ",
                                            "                                                                     ",
                                            "                                                                     ",
                                            "                                                                     ",
                                            "                                                                     ",
                                            "                                                                     ",
                                            "                                                                     ",
                                            "                                                                     ",
                                            "                                                                     ",
                                            "                                                                     ",
                                            "                                                                     ",
                                            "                                                                     ",
                                            "                                                                     ",
                                            "                                                                     ",
                                            "                                                                     ",
                                            "                                                                     ",
                                            "                                                                     ",
                                            "                                                                     ",
                                            "                                                                     ",
                                            "                                                                     ",
                                            "                                                                     ",
                                            "                                                                     ",
                                            "                                                                     ",
                                            "                                                                     ",
                                            "                                                                     ",
                                            "                                                                     ",
                                            "                                                                     ",
                                            "                                                                     ",
                                            "                                                                     ",
                                            "                                                                     " },
                                    { "                                                                     ",
                                            "                                                                     ",
                                            "                                                                     ",
                                            "                                                                     ",
                                            "                                                                     ",
                                            "                                                                     ",
                                            "                                                                     ",
                                            "                                                                     ",
                                            "                                                                     ",
                                            "                                                                     ",
                                            "                                                                     ",
                                            "                                                                     ",
                                            "                                                                     ",
                                            "                                                                     ",
                                            "                                                                     ",
                                            "                                                                     ",
                                            "                                                                     ",
                                            "                                                                     ",
                                            "                                                                     ",
                                            "                                                                     ",
                                            "                                                                     ",
                                            "                                                                     ",
                                            "                                                                     ",
                                            "                                C                                    ",
                                            "                               CCCCCC                                ",
                                            "                               CCCCCCC                               ",
                                            "                                CCCDDCCC                             ",
                                            "                                 CC DDDCC                            ",
                                            "                                  CCCDDDCC                           ",
                                            "                                    CCCCCCC                          ",
                                            "                                      CCCCCC                         ",
                                            "                                        CCCC                         ",
                                            "                                                                     ",
                                            "                                                                     ",
                                            "                                                                     ",
                                            "                                                                     ",
                                            "                                                                     ",
                                            "                                                                     ",
                                            "                                                                     ",
                                            "                                                                     ",
                                            "                                                                     ",
                                            "                                                                     ",
                                            "                                                                     ",
                                            "                                                                     ",
                                            "                                                                     ",
                                            "                                                                     ",
                                            "                                                                     ",
                                            "                                                                     ",
                                            "                                                                     ",
                                            "                                                                     ",
                                            "                                                                     ",
                                            "                                                                     ",
                                            "                                                                     ",
                                            "                                                                     ",
                                            "                                                                     ",
                                            "                                                                     ",
                                            "                                                                     ",
                                            "                                                                     ",
                                            "                                                                     ",
                                            "                                                                     ",
                                            "                                                                     ",
                                            "                                                                     ",
                                            "                                                                     ",
                                            "                                                                     ",
                                            "                                                                     " },
                                    { "                                                                     ",
                                            "                                                                     ",
                                            "                                                                     ",
                                            "                                                                     ",
                                            "                                                                     ",
                                            "                                                                     ",
                                            "                                                                     ",
                                            "                                                                     ",
                                            "                                                                     ",
                                            "                                                                     ",
                                            "                                                                     ",
                                            "                                                                     ",
                                            "                                                                     ",
                                            "                                                                     ",
                                            "                                                                     ",
                                            "                                                                     ",
                                            "                                                                     ",
                                            "                                                                     ",
                                            "                                                                     ",
                                            "                                                                     ",
                                            "                                                                     ",
                                            "                                                                     ",
                                            "                             CCCC                                    ",
                                            "                            CCCC CCC                                 ",
                                            "                            CCCDDDD CC                               ",
                                            "                             CCDDDDDD C                              ",
                                            "                              CCDDDDDDDCC                            ",
                                            "                                C DDDDDDDC                           ",
                                            "                                 CCDDDDDDDCC                         ",
                                            "                                   CCDDDDDDCC                        ",
                                            "                                     C DDDD C                        ",
                                            "                                      CC DD CC                       ",
                                            "                                        CCCCCC                       ",
                                            "                                           CC                        ",
                                            "                                                                     ",
                                            "                                                                     ",
                                            "                                                                     ",
                                            "                                                                     ",
                                            "                                                                     ",
                                            "                                                                     ",
                                            "                                                                     ",
                                            "                                                                     ",
                                            "                                                                     ",
                                            "                                                                     ",
                                            "                                                                     ",
                                            "                                                                     ",
                                            "                                                                     ",
                                            "                                                                     ",
                                            "                                                                     ",
                                            "                                                                     ",
                                            "                                                                     ",
                                            "                                                                     ",
                                            "                                                                     ",
                                            "                                                                     ",
                                            "                                                                     ",
                                            "                                                                     ",
                                            "                                                                     ",
                                            "                                                                     ",
                                            "                                                                     ",
                                            "                                                                     ",
                                            "                                                                     ",
                                            "                                                                     ",
                                            "                                                                     ",
                                            "                                                                     ",
                                            "                                                                     " },
                                    { "                                                                     ",
                                            "                                                                     ",
                                            "                                                                     ",
                                            "                                                                     ",
                                            "                                                                     ",
                                            "                                                                     ",
                                            "                                                                     ",
                                            "                                                                     ",
                                            "                                                                     ",
                                            "                                                                     ",
                                            "                                                                     ",
                                            "                                                                     ",
                                            "                                                                     ",
                                            "                                                                     ",
                                            "                                                                     ",
                                            "                                                                     ",
                                            "                                                                     ",
                                            "                                                                     ",
                                            "                                                                     ",
                                            "                                                                     ",
                                            "                                                                     ",
                                            "                            CCC                                      ",
                                            "                           CC  CCC                                   ",
                                            "                          CC DDDDDCC                                 ",
                                            "                           C DDDDDDDCC                               ",
                                            "                            C DDDDDDDDCC                             ",
                                            "                             CCDDDDDDDD C                            ",
                                            "                               CCDDDDDDDDCC                          ",
                                            "                                 CCDDDDDDDDC                         ",
                                            "                                   C DDDDDDDC                        ",
                                            "                                    CCDDDDDDDC                       ",
                                            "                                      CCDDDDD C                      ",
                                            "                                        C DDDDC                      ",
                                            "                                         CC  CC                      ",
                                            "                                           CCCC                      ",
                                            "                                                                     ",
                                            "                                                                     ",
                                            "                                                                     ",
                                            "                                                                     ",
                                            "                                                                     ",
                                            "                                                                     ",
                                            "                                                                     ",
                                            "                                                                     ",
                                            "                                                                     ",
                                            "                                                                     ",
                                            "                                                                     ",
                                            "                                                                     ",
                                            "                                                                     ",
                                            "                                                                     ",
                                            "                                                                     ",
                                            "                                                                     ",
                                            "               CCC                                                   ",
                                            "                CCCC                                                 ",
                                            "                CCCCCC                                               ",
                                            "                 CCCCCCC                                             ",
                                            "                  CCCCCCC                                            ",
                                            "                    CCCCCCC                                          ",
                                            "                     CCCCCCC                                         ",
                                            "                        CCCC                                         ",
                                            "                                                                     ",
                                            "                                                                     ",
                                            "                                                                     ",
                                            "                                                                     ",
                                            "                                                                     ",
                                            "                                                                     " },
                                    { "                                                                     ",
                                            "                                                                     ",
                                            "                                                                     ",
                                            "                                                                     ",
                                            "                                                                     ",
                                            "                                                                     ",
                                            "                                                                     ",
                                            "                                                                     ",
                                            "                                                                     ",
                                            "                                                                     ",
                                            "                                                                     ",
                                            "                                                                     ",
                                            "                                                                     ",
                                            "                                                                     ",
                                            "                                                                     ",
                                            "                                                                     ",
                                            "                                                                     ",
                                            "                                                                     ",
                                            "                                                                     ",
                                            "                                                                     ",
                                            "                                                                     ",
                                            "                         CCCCCCC                                     ",
                                            "                         CCDDDDDCC                                   ",
                                            "                         C DDDDDDDCC                                 ",
                                            "                          CDDDDDDDD CC                               ",
                                            "                           CCDDDDDDDD C                              ",
                                            "                             CCDDDDDDDDCC                            ",
                                            "                               CCDDDDDDDDCC                          ",
                                            "                                 CC DDDDDD C                         ",
                                            "                                   CCDDDDDDDCC                       ",
                                            "                                     C DDDDDD C                      ",
                                            "                                      CCDDDDDD C                     ",
                                            "                                        CDDDDDDC                     ",
                                            "                                         C DDDDCC                    ",
                                            "                                          CC DDCC                    ",
                                            "                                            CCCC                     ",
                                            "                                                                     ",
                                            "                                                                     ",
                                            "                                                                     ",
                                            "                                                                     ",
                                            "                                                                     ",
                                            "                                                                     ",
                                            "                                                                     ",
                                            "                                                                     ",
                                            "                                                                     ",
                                            "                                                                     ",
                                            "           CCC                                                       ",
                                            "           CCCC                                                      ",
                                            "           CCCCCC                                                    ",
                                            "           CCCCCCCC                                                  ",
                                            "            CCCCCCCC                                                 ",
                                            "            CCCDDDCCCC                                               ",
                                            "             CCCDDDDCCC                                              ",
                                            "              CCDDDDDDCCC                                            ",
                                            "               CCDDDDDD CCC                                          ",
                                            "                CC DDDDDDCCCC                                        ",
                                            "                 CCCDDDDDDDCCCC                                      ",
                                            "                  CCC DDDDDDCCCCC                                    ",
                                            "                    CCCC DDDCCCCCC                                   ",
                                            "                      CCCCCCCCCCCC                                   ",
                                            "                         CCCCCCCCC                                   ",
                                            "                                                                     ",
                                            "                                                                     ",
                                            "                                                                     ",
                                            "                                                                     " },
                                    { "                                                                     ",
                                            "                                                                     ",
                                            "                                                                     ",
                                            "                                                                     ",
                                            "                                                                     ",
                                            "                                                                     ",
                                            "                                                                     ",
                                            "                                                                     ",
                                            "                                                                     ",
                                            "                                                                     ",
                                            "                                                                     ",
                                            "                                                                     ",
                                            "                                                                     ",
                                            "                                                                     ",
                                            "                                                                     ",
                                            "                                                                     ",
                                            "                                                                     ",
                                            "                                                                     ",
                                            "                                                                     ",
                                            "                                                                     ",
                                            "                         CCCC                                        ",
                                            "                        C DDDCCC                                     ",
                                            "                        CDDDDDD C                                    ",
                                            "                        C DDDDDDDCC                                  ",
                                            "                         C DDDDDDDCC                                 ",
                                            "                          CC DDDDDDCCC                               ",
                                            "                            CCCC DDCCCCC                             ",
                                            "                                CCCCCCCCCC                           ",
                                            "                                   CCCCCCCCC                         ",
                                            "                                     CC DDD CC                       ",
                                            "                                      CCDDDDD C                      ",
                                            "                                       CCDDDDDDC                     ",
                                            "                                        C DDDDDDC                    ",
                                            "                                         C DDDDDC                    ",
                                            "                                          CCDDDD C                   ",
                                            "                                            C DDCC                   ",
                                            "                                             CCCC                    ",
                                            "                                                                     ",
                                            "                                                                     ",
                                            "                                                                     ",
                                            "                                                                     ",
                                            "                                                                     ",
                                            "         C                                                           ",
                                            "        CCCC                                                         ",
                                            "        CCCCCC                                                       ",
                                            "        CCCCCCC                                                      ",
                                            "        CCCDD CC                                                     ",
                                            "         CCDDDDCC                                                    ",
                                            "         CCDDDDD CC                                                  ",
                                            "         CCDDDDDDD C                                                 ",
                                            "          CCDDDDDDD CC                                               ",
                                            "           C DDDDDDDD C                                              ",
                                            "            CDDDDDDDDDDCC                                            ",
                                            "            CCDDDDDDDDDD CC                                          ",
                                            "             CCDDDDDDDDDDD CC                                        ",
                                            "              CCDDDDDDDDDDDD CCC                                     ",
                                            "                C DDDDDDDDDDDD CCC                                   ",
                                            "                 C DDDDDDDDDDDDD CCC                                 ",
                                            "                  CC DDDDDDDDDDDDDCCCC                               ",
                                            "                    CC DDDDDDDDDDDCCCC                               ",
                                            "                      CCC DDDDDDD CCCC                               ",
                                            "                         CCCCCCCCCCCC                                ",
                                            "                             CCCCC                                   ",
                                            "                                                                     ",
                                            "                                                                     " },
                                    { "                                                                     ",
                                            "                                                                     ",
                                            "                                                                     ",
                                            "                                                                     ",
                                            "                                                                     ",
                                            "                                                                     ",
                                            "                                                                     ",
                                            "                                                                     ",
                                            "                                                                     ",
                                            "                                                                     ",
                                            "                                                                     ",
                                            "                                                                     ",
                                            "                                                                     ",
                                            "                                                                     ",
                                            "                                                                     ",
                                            "                                                                     ",
                                            "                                                                     ",
                                            "                                                                     ",
                                            "                                                                     ",
                                            "                                                                     ",
                                            "                       CCCCCC                                        ",
                                            "                       CDDDDDCC                                      ",
                                            "                       CDDDDDD C                                     ",
                                            "                       C DDDDDD C                                    ",
                                            "                        CCDDDDDDCC                                   ",
                                            "                          CCCC CCCC                                  ",
                                            "                              CCCCC                                  ",
                                            "                                                                     ",
                                            "                                                                     ",
                                            "                                       CCCCCC                        ",
                                            "                                        CCCC CC                      ",
                                            "                                         CCDDD C                     ",
                                            "                                         CCDDDDDC                    ",
                                            "                                          CDDDDDDC                   ",
                                            "                                           CDDDDDC                   ",
                                            "                                            CDDDD C                  ",
                                            "                                             C DDCC                  ",
                                            "                                              CCCC                   ",
                                            "                                                                     ",
                                            "        C                                                            ",
                                            "      CCCCC                                                          ",
                                            "      CCCCCC                                                         ",
                                            "      CCC CCC                                                        ",
                                            "      CCDDDDCC                                                       ",
                                            "      CCDDDDD C                                                      ",
                                            "       CDDDDDD C                                                     ",
                                            "       C DDDDDD C                                                    ",
                                            "       CCDDDDDDDDC                                                   ",
                                            "        CDDDDDDDDDCC                                                 ",
                                            "        C DDDDDDDDD C                                                ",
                                            "         C DDDDDDDDDDCC                                              ",
                                            "          CDDDDDDDDDDD C                                             ",
                                            "           CDDDDDDDDDDDDCC                                           ",
                                            "            CDDDDDDDDDDDDDCC                                         ",
                                            "            CCDDDDDDDDDDDDDDCCC                                      ",
                                            "              CDDDDDDDDDDDDDDD CCC                                   ",
                                            "               C DDDDDDDDDDDDDDDD CCCC                               ",
                                            "                CCDDDDDDDDDDDDDDDDDDCCCC                             ",
                                            "                  C DDDDDDDDDDDDDDDDDDCCC                            ",
                                            "                   CCDDDDDDDDDDDDDDDDDCCCC                           ",
                                            "                     CC DDDDDDDDDDDDDDCCCC                           ",
                                            "                       CCC DDDDDDDDDDCCCC                            ",
                                            "                          CCCCCC  CCCCC                              ",
                                            "                                CC                                   ",
                                            "                                                                     " },
                                    { "                                                                     ",
                                            "                                                                     ",
                                            "                                                                     ",
                                            "                                                                     ",
                                            "                                                                     ",
                                            "                                                                     ",
                                            "                                                                     ",
                                            "                                                                     ",
                                            "                                                                     ",
                                            "                                                                     ",
                                            "                                                                     ",
                                            "                                                                     ",
                                            "                                                                     ",
                                            "                                                                     ",
                                            "                                                                     ",
                                            "                                                                     ",
                                            "                                                                     ",
                                            "                                                                     ",
                                            "                                                                     ",
                                            "                       CCCC                                          ",
                                            "                      C DD CC                                        ",
                                            "                     CCDDDDD C                                       ",
                                            "                      CDDDDDD C                                      ",
                                            "                      C DDDDD CC                                     ",
                                            "                       CCCDD CCC                                     ",
                                            "                          CCCCC                                      ",
                                            "                                                                     ",
                                            "                                                                     ",
                                            "                                                                     ",
                                            "                                                                     ",
                                            "                                            C                        ",
                                            "                                           CCCCC                     ",
                                            "                                           C DDDC                    ",
                                            "                                           CDDDDDC                   ",
                                            "                                           C DDDDDC                  ",
                                            "                                            CDDDDDC                  ",
                                            "                                             CDDDDC                  ",
                                            "     CCCC                                     CCD C                  ",
                                            "     CCCCC                                      CC                   ",
                                            "     CCC CC                                                          ",
                                            "     C DDD C                                                         ",
                                            "     CDDDDD C                                                        ",
                                            "     CDDDDDD C                                                       ",
                                            "     C DDDDDD C                                                      ",
                                            "     C DDDDDDD C                                                     ",
                                            "      CDDDDDDDD C                                                    ",
                                            "      CDDDDDDDDD C                                                   ",
                                            "       CDDDDDDDDD C                                                  ",
                                            "       C DDDDDDDDD C                                                 ",
                                            "        CDDDDDDDDDDDC                                                ",
                                            "         CDDDDDDDDDDDCC                                              ",
                                            "         C DDDDDDDDDDDDCC                                            ",
                                            "          C DDDDDDDDDDDD CC                                          ",
                                            "           CDDDDDDDDDDDDDDDCC                                        ",
                                            "            C DDDDDDDDDDDDDDDCCC                                     ",
                                            "             C DDDDDDDDDDDDDDDDDCCCCC                                ",
                                            "              CCDDDDDDDDDDDDDDDDDDDD CCCC                            ",
                                            "                CDDDDDDDDDDDDDDDDDDDDDD CCCC                         ",
                                            "                 CCDDDDDDDDDDDDDDDDDDDDDDCCCC                        ",
                                            "                   CCDDDDDDDDDDDDDDDDDDDDDCCC                        ",
                                            "                     CCDDDDDDDDDDDDDDDDDDDCCC                        ",
                                            "                       CCDDDDDDDDDDDDDDD CCC                         ",
                                            "                         CCCCDDDDDDDDD CCC                           ",
                                            "                             CCCCCCCCCCC                             ",
                                            "                                                                     " },
                                    { "                                                                     ",
                                            "                                                                     ",
                                            "                                                                     ",
                                            "                                                                     ",
                                            "                                                                     ",
                                            "                                                                     ",
                                            "                                                                     ",
                                            "                                                                     ",
                                            "                                                                     ",
                                            "                                                                     ",
                                            "                                                                     ",
                                            "                                                                     ",
                                            "                                                                     ",
                                            "                                                                     ",
                                            "                                                                     ",
                                            "                                                                     ",
                                            "                                                                     ",
                                            "                                                                     ",
                                            "                                                                     ",
                                            "                      CCCC                                           ",
                                            "                     C DDDCC                                         ",
                                            "                     CDDDDD C                                        ",
                                            "                     CDDDDDDCC                                       ",
                                            "                     CCDDDDDCC                                       ",
                                            "                       CCCCCC                                        ",
                                            "                                                                     ",
                                            "                                                                     ",
                                            "                                                                     ",
                                            "                                                                     ",
                                            "                                                                     ",
                                            "                                                                     ",
                                            "                                                                     ",
                                            "                                            CCCCC                    ",
                                            "                                            CCDDDC                   ",
                                            "     CCC                                    C DDDDC                  ",
                                            "    CCCCC                                    CDDDDDC                 ",
                                            "    CCCCCC                                   CDDDDDC                 ",
                                            "    C DDDCC                                   CDDDDC                 ",
                                            "    CDDDDDC                                    CCCCC                 ",
                                            "    CDDDDDDC                                                         ",
                                            "    CDDDDDD C                                                        ",
                                            "    CDDDDDDD C                                                       ",
                                            "    CDDDDDDDDC                                                       ",
                                            "    C DDDDDDDDC                                                      ",
                                            "     CDDDDDDDDDC                                                     ",
                                            "     CDDDDDDDDDDC                                                    ",
                                            "      CDDDDDDDDDDC                                                   ",
                                            "      CDDDDDDDDDDDC                                                  ",
                                            "       CDDDDDDDDDDDC                                                 ",
                                            "       C DDDDDDDDDDDCC                                               ",
                                            "        CDDDDDDDDDDDD C                                              ",
                                            "         CDDDDDDDDDDDDDCC                                            ",
                                            "          CDDDDDDDDDDDDDDCC                                          ",
                                            "           CDDDDDDDDDDDDDDDCCC                                       ",
                                            "            CDDDDDDDDDDDDDDDD CCC                                    ",
                                            "             C DDDDDDDDDDDDDDDDDDCCCCCCCC                            ",
                                            "              CCDDDDDDDDDDDDDDDDDDDDDDD  CCCCC                       ",
                                            "                CDDDDDDDDDDDDDDDDDDDDDDDDDD CCC                      ",
                                            "                 CCDDDDDDDDDDDDDDDDDDDDDDDDDDCCC                     ",
                                            "                   C DDDDDDDDDDDDDDDDDDDDDDDDCC                      ",
                                            "                    CCCDDDDDDDDDDDDDDDDDDDDD CC                      ",
                                            "                       CCDDDDDDDDDDDDDDDDDD CC                       ",
                                            "                         CCCDDDDDDDDDDDDD CC                         ",
                                            "                            CCCCCCC CCCCCC                           ",
                                            "                                   C                                 " },
                                    { "                                                                     ",
                                            "                                                                     ",
                                            "                                                                     ",
                                            "                                                                     ",
                                            "                                                                     ",
                                            "                                                                     ",
                                            "                                                                     ",
                                            "                                                                     ",
                                            "                                                                     ",
                                            "                                                                     ",
                                            "                                                                     ",
                                            "                                                                     ",
                                            "                                                                     ",
                                            "                                                                     ",
                                            "                                                                     ",
                                            "                                                                     ",
                                            "                                                                     ",
                                            "                                                                     ",
                                            "                                                                     ",
                                            "                     CCCCC                                           ",
                                            "                    CDDDDDC                                          ",
                                            "                    CDDDDD C                                         ",
                                            "                    CDDDDDDC                                         ",
                                            "                     CDDDDCC                                         ",
                                            "                      CCCCC                                          ",
                                            "                                                                     ",
                                            "                                                                     ",
                                            "                                                                     ",
                                            "                                                                     ",
                                            "                                                                     ",
                                            "                                                                     ",
                                            "                                                                     ",
                                            "    CCCC                                                             ",
                                            "   CCCCCC                                     CCCC                   ",
                                            "   CCDD C                                    CCDDDC                  ",
                                            "   C DDD C                                   C DDDDC                 ",
                                            "   CDDDDD C                                   CDDDD C                ",
                                            "   CDDDDDDC                                   CDDDDDC                ",
                                            "   CDDDDDDDC                                   CDDDCB                ",
                                            "   CDDDDDDD C                                   CCCCB                ",
                                            "   CDDDDDDDDC                                      BB                ",
                                            "   CDDDDDDDDDC                                                       ",
                                            "    CDDDDDDDD C                                                      ",
                                            "    CDDDDDDDDDC                                                      ",
                                            "    C DDDDDDDDDC                                                     ",
                                            "     CDDDDDDDDDDC                                                    ",
                                            "     C DDDDDDDDDDC                                                   ",
                                            "      CDDDDDDDDDD C                                                  ",
                                            "       CDDDDDDDDDD C                                                 ",
                                            "       C DDDDDDDDDDDC                                                ",
                                            "        CDDDDDDDDDDDDCC                                              ",
                                            "         CDDDDDDDDDDDD C                                             ",
                                            "          CDDDDDDDDDDDDDCC                                           ",
                                            "           CDDDDDDDDDDDDDDCCC                                        ",
                                            "            C DDDDDDDDDDDDDDDCCCCC                                   ",
                                            "             C DDDDDDDDDDDDDDDDDDDCCCCCCCCCCCCC                      ",
                                            "              CCDDDDDDDDDDDDDDDDDDDDDDDDDDDD  CCC                    ",
                                            "                C DDDDDDDDDDDDDDDDDDDDDDDDDDDDDCCC                   ",
                                            "                 CCDDDDDDDDDDDDDDDDDDDDDDDDDDDD CC                   ",
                                            "                   CCDDDDDDDDDDDDDDDDDDDDDDDDDDCC                    ",
                                            "                     CCDDDDDDDDDDDDDDDDDDDDDDD CC                    ",
                                            "                       CC DDDDDDDDDDDDDDDDDDD CC                     ",
                                            "                         CCC DDDDDDDDDDDDDD CC                       ",
                                            "                            CCCCCDDDDDDDCCCC                         ",
                                            "                                 CCCCCCC                             " },
                                    { "                                                                     ",
                                            "                                                                     ",
                                            "                                                                     ",
                                            "                                                                     ",
                                            "                                                                     ",
                                            "                                                                     ",
                                            "                                                                     ",
                                            "                                                                     ",
                                            "                                                                     ",
                                            "                                                                     ",
                                            "                                                                     ",
                                            "                                                                     ",
                                            "                                                                     ",
                                            "                                                                     ",
                                            "                                                                     ",
                                            "                                                                     ",
                                            "                                                                     ",
                                            "                                                                     ",
                                            "                                                                     ",
                                            "                  BBCCCCC                                            ",
                                            "                  BC DDDDC                                           ",
                                            "                  BCDDDDD C                                          ",
                                            "                   C DDDD C                                          ",
                                            "                    CCDD C                                           ",
                                            "                      CCC                                            ",
                                            "                                                                     ",
                                            "                                                                     ",
                                            "                                                                     ",
                                            "                                                                     ",
                                            "     C                                                               ",
                                            "   CCCCC                                                             ",
                                            "   CCCCC                                                             ",
                                            "  CCDDD C                                                            ",
                                            "  C DDDD C                                                           ",
                                            "  CDDDDDDC                                     CCCC                  ",
                                            "  CDDDDDD C                                   C DDDC                 ",
                                            "  CDDDDDDDC                                   CDDDDDC                ",
                                            "  CDDDDDDDDC                                   CDDDDC                ",
                                            "  CDDDDDDDDC                                   CDDDDCB               ",
                                            "  CDDDDDDDDDC                                   C D CB               ",
                                            "   CDDDDDDDDC                                    CCCBB               ",
                                            "   CDDDDDDDDDC                                                       ",
                                            "   CDDDDDDDDD C                                                      ",
                                            "    CDDDDDDDDDC                                                      ",
                                            "    CDDDDDDDDDDC                                                     ",
                                            "     CDDDDDDDDD C                                                    ",
                                            "     CDDDDDDDDDD C                                                   ",
                                            "      CDDDDDDDDDDC                                                   ",
                                            "       CDDDDDDDDDDC                                                  ",
                                            "       C DDDDDDDDDDCC                                                ",
                                            "        C DDDDDDDDDD C                                               ",
                                            "         C DDDDDDDDDD CC                                             ",
                                            "          C DDDDDDDDDDD C                                            ",
                                            "           C DDDDDDDDDDDDCCC                                         ",
                                            "            CCDDDDDDDDDDDDDDCCCCC            CCC                     ",
                                            "              C DDDDDDDDDDDDDDDD CCCCCCCCCCCC  CCCC                  ",
                                            "               CCDDDDDDDDDDDDDDDDDDDDDDDDDDDDDDDDCCC                 ",
                                            "                 C DDDDDDDDDDDDDDDDDDDDDDDDDDDDDDDCC                 ",
                                            "                  CCDDDDDDDDDDDDDDDDDDDDDDDDDDDDDDCC                 ",
                                            "                    CCDDDDDDDDDDDDDDDDDDDDDDDDDDDCC                  ",
                                            "                      CCDDDDDDDDDDDDDDDDDDDDDDDD C                   ",
                                            "                        CC DDDDDDDDDDDDDDDDDDDD C                    ",
                                            "                          CCC DDDDDDDDDDDDDDDCCC                     ",
                                            "                             CCCCCDDDDDDD CCC                        ",
                                            "                                  CCCCCCCC                           " },
                                    { "                                                                     ",
                                            "                                                                     ",
                                            "                                                                     ",
                                            "                                                                     ",
                                            "                                                                     ",
                                            "                                                                     ",
                                            "                                                                     ",
                                            "                                                                     ",
                                            "                                                                     ",
                                            "                                                                     ",
                                            "                                                                     ",
                                            "                                                                     ",
                                            "                                                                     ",
                                            "                                                                     ",
                                            "                                                                     ",
                                            "                                                                     ",
                                            "                                                                     ",
                                            "                                                                     ",
                                            "                 BB  C                                               ",
                                            "                 BBCCDCCC                                            ",
                                            "                 BC DDDD C                                           ",
                                            "                  CDDDDDDC                                           ",
                                            "                   CDDDD C                                           ",
                                            "                   CCC CC                                            ",
                                            "                      C                                              ",
                                            "                                                                     ",
                                            "                                                                     ",
                                            "    CC                                                               ",
                                            "   CCCCC                                                             ",
                                            "  CCC CC                                                             ",
                                            "  C DDD C                                                            ",
                                            "  CDDDDDC                                                            ",
                                            "  CDDDDDDC                                                           ",
                                            " C DDDDDDC                                                           ",
                                            " C DDDDDDDC                                     CCC                  ",
                                            " C DDDDDDDC                                    C D C                 ",
                                            "  CDDDDDDD C                                   CDDDDC                ",
                                            "  CDDDDDDDDC                                   CDDDDC                ",
                                            "  CDDDDDDDDC                                   CDDDDDC               ",
                                            "  CDDDDDDDDDC                                   CDDDCB               ",
                                            "  CDDDDDDDDDC                                    CCCCBB              ",
                                            "   CDDDDDDDDDC                                       B               ",
                                            "   CDDDDDDDDDC                                                       ",
                                            "    CDDDDDDDDDC                                                      ",
                                            "    CDDDDDDDDD C                                                     ",
                                            "     CDDDDDDDDDC                                                     ",
                                            "     C DDDDDDDD C                                                    ",
                                            "      C DDDDDDDD C                                                   ",
                                            "       CDDDDDDDDDCC                                                  ",
                                            "        CDDDDDDDDDCC                                                 ",
                                            "         CDDDDDDDDDCC                                                ",
                                            "          C DDDDDDDDCC                                               ",
                                            "           C DDDDDDDDCCC                                             ",
                                            "            CCDDDDDDDD CCC                                           ",
                                            "             CC DDDDDDDDDCCCCC            CCCCCCCCCCC                ",
                                            "               CCDDDDDDDDDDD  CCCCCCCCCCCCDDDDDDDDDCCC               ",
                                            "                CCCDDDDDDDDDDDDDDDDDDDDDDDDDDDDDDDDDCC               ",
                                            "                  CC DDDDDDDDDDDDDDDDDDDDDDDDDDDDDDDCC               ",
                                            "                    CC DDDDDDDDDDDDDDDDDDDDDDDDDDDD C                ",
                                            "                     CCCDDDDDDDDDDDDDDDDDDDDDDDDDDDCC                ",
                                            "                       CCCDDDDDDDDDDDDDDDDDDDDDDDDCC                 ",
                                            "                         CCC DDDDDDDDDDDDDDDDDDD C                   ",
                                            "                            CCC DDDDDDDDDDDDDDCCC                    ",
                                            "                               CCCCCDDDDDDCCCC                       ",
                                            "                                    CCCCCC                           " },
                                    { "                                                                     ",
                                            "                                                                     ",
                                            "                                                                     ",
                                            "                                                                     ",
                                            "                                                                     ",
                                            "                                                                     ",
                                            "                                                                     ",
                                            "                                                                     ",
                                            "                                                                     ",
                                            "                                                                     ",
                                            "                                                                     ",
                                            "                                                                     ",
                                            "                                                                     ",
                                            "                                                                     ",
                                            "                                                                     ",
                                            "                                                                     ",
                                            "                                                                     ",
                                            "                                                                     ",
                                            "                BB  CC                                               ",
                                            "                BBCCDDCC                                             ",
                                            "                 BCDDDD C                                            ",
                                            "                  CDDDDDC                                            ",
                                            "                  CDDDD C                                            ",
                                            "                   CCCCC                                             ",
                                            "                                                                     ",
                                            "    CCC                                                              ",
                                            "   CCCCC                                                             ",
                                            "  CC DCC                                                             ",
                                            "  C DDD C                                                            ",
                                            "  CDDDDDC                                                            ",
                                            " C DDDDD C                                                           ",
                                            " CDDDDDDDC                                                           ",
                                            " CDDDDDDDC                                                           ",
                                            " CDDDDDDDDC                                                          ",
                                            " CDDDDDDDDC                                                          ",
                                            " CDDDDDDDDC                                     CCCC                 ",
                                            " CDDDDDDDDDC                                    CDDDC                ",
                                            " C DDDDDDDDC                                   C DDDDC               ",
                                            "  CDDDDDDDDC                                    CDDDDC               ",
                                            "  CDDDDDDDDDC                                   CDDDDC               ",
